<mujoco model="unnamed_model">
  <option timestep="0.01" integrator="RK4">
    <flag energy="enable" sensornoise="enable"/>
  </option>
  <default>
    <default class="/"/>
  </default>
  <worldbody>
    <light name="world_light" class="/" pos="0 0 10" dir="0 0 -1" diffuse="0.5 0.5 0.5"/>
    <geom name="ground_plane" class="/" type="plane" size="0 0 1" rgba="0.5 0 0.5 1"/>
    <body name="core_body" pos="0 0 2.8267341911491668">
      <geom name="core_geom" class="/" type="box" size="1 1.9936767153702086 2.8267341911491668" rgba="0 0.90000000000000002 0 1"/>
      <joint name="first" class="/" type="free"/>
      <body name="front_limb_1" pos="0 -7.1679273635493495 0">
        <joint name="front_shoulder_1" class="/" type="ball" pos="0 5.1742506481791413 0"/>
        <geom name="front_arm_1" class="/" type="box" size="0.20000000000000001 5.1742506481791413 0.20000000000000001" rgba="0 0 0.69999999999999996 1" mass="1"/>
        <body name="front_limb_2" pos="0 -7.7613759722687119 0">
          <joint name="front_shoulder_2" class="/" type="ball" pos="0 2.5871253240895706 0"/>
          <geom name="front_arm_2" class="/" type="box" size="0.10000000000000001 2.5871253240895706 0.10000000000000001" rgba="0 0 0.80000000000000004 1" mass="1"/>
          <body name="front_limb_3" pos="0 -3.8806879861343559 0">
            <joint name="front_shoulder_3" class="/" type="ball" pos="0 1.2935626620447853 0"/>
            <geom name="front_arm_3" class="/" type="box" size="0.050000000000000003 1.2935626620447853 0.050000000000000003" rgba="0 0 0.90000000000000002 1" mass="1"/>
            <body name="front_limb_4" pos="0 -1.940343993067178 0">
              <joint name="front_shoulder_4" class="/" type="ball" pos="0 0.64678133102239266 0"/>
              <geom name="front_arm_4" class="/" type="box" size="0.025000000000000001 0.64678133102239266 0.025000000000000001" rgba="0 0 1 1" mass="1"/>
            </body>
          </body>
        </body>
      </body>
      <body name="left_limb_5" pos="-4.3085720670714558 0 0">
        <joint name="left_shoulder_5" class="/" type="ball" pos="3.3085720670714558 0 0"/>
        <geom name="left_arm_5" class="/" type="box" size="3.3085720670714558 0.39116770043783072 0.39116770043783072" rgba="0 0 1 1" mass="1"/>
      </body>
      <body name="back_limb_6" pos="0 5.2207382355153813 0">
        <joint name="back_shoulder_6" class="/" type="ball" pos="0 -3.2270615201451727 0"/>
        <geom name="back_arm_6" class="/" type="box" size="0.32253289967636206 3.2270615201451727 0.32253289967636206" rgba="0 0 1 1" mass="1"/>
      </body>
    </body>
  </worldbody>
  <actuator>
    <position name="frontxy_3" class="/" group="0" gear="0 0 1" joint="front_shoulder_1" kp="5"/>
    <position name="frontxz_3" class="/" group="0" gear="0 1 0" joint="front_shoulder_1" kp="5"/>
    <position name="frontyz_3" class="/" group="0" gear="1 0 0" joint="front_shoulder_1" kp="5"/>
    <position name="frontxy_2" class="/" group="0" gear="0 0 1" joint="front_shoulder_2" kp="5"/>
    <position name="frontxz_2" class="/" group="0" gear="0 1 0" joint="front_shoulder_2" kp="5"/>
    <position name="frontyz_2" class="/" group="0" gear="1 0 0" joint="front_shoulder_2" kp="5"/>
    <position name="frontxy_1" class="/" group="0" gear="0 0 1" joint="front_shoulder_3" kp="5"/>
    <position name="frontxz_1" class="/" group="0" gear="0 1 0" joint="front_shoulder_3" kp="5"/>
    <position name="frontyz_1" class="/" group="0" gear="1 0 0" joint="front_shoulder_3" kp="5"/>
    <position name="frontxy_0" class="/" group="0" gear="0 0 1" joint="front_shoulder_4" kp="5"/>
    <position name="frontxz_0" class="/" group="0" gear="0 1 0" joint="front_shoulder_4" kp="5"/>
    <position name="frontyz_0" class="/" group="0" gear="1 0 0" joint="front_shoulder_4" kp="5"/>
    <position name="leftxy_0" class="/" group="3" gear="0 0 1" joint="left_shoulder_5" kp="5"/>
    <position name="leftxz_0" class="/" group="3" gear="0 1 0" joint="left_shoulder_5" kp="5"/>
    <position name="leftyz_0" class="/" group="3" gear="1 0 0" joint="left_shoulder_5" kp="5"/>
    <position name="backxy_0" class="/" group="2" gear="0 0 1" joint="back_shoulder_6" kp="5"/>
    <position name="backxz_0" class="/" group="2" gear="0 1 0" joint="back_shoulder_6" kp="5"/>
    <position name="backyz_0" class="/" group="2" gear="1 0 0" joint="back_shoulder_6" kp="5"/>
  </actuator>
</mujoco>
