<mujoco model="unnamed_model">
  <option timestep="0.01" integrator="RK4">
    <flag energy="enable" sensornoise="enable"/>
  </option>
  <default>
    <default class="/"/>
  </default>
  <worldbody>
    <light name="world_light" class="/" pos="0 0 10" dir="0 0 -1" diffuse="0.5 0.5 0.5"/>
    <geom name="ground_plane" class="/" type="plane" size="0 0 1" rgba="0.5 0 0.5 1"/>
    <body name="core_body" pos="0 0 2.7874631059999699">
      <geom name="core_geom" class="/" type="box" size="1.2575567350350823 1.949356552523215 2.7874631059999699" rgba="0 0.90000000000000002 0 1"/>
      <joint name="first" class="/" type="free"/>
      <body name="front_limb_13" pos="0 -6.3409077929930859 0">
        <joint name="front_shoulder_13" class="/" type="ball" pos="0 4.3915512404698713 0"/>
        <geom name="front_arm_13" class="/" type="box" size="0.81799823508897429 4.3915512404698713 0.81799823508897429" rgba="0 0 0.69999999999999996 1" mass="1"/>
        <body name="front_limb_14" pos="0 -6.587326860704807 0">
          <joint name="front_shoulder_14" class="/" type="ball" pos="0 2.1957756202349357 0"/>
          <geom name="front_arm_14" class="/" type="box" size="0.40899911754448715 2.1957756202349357 0.40899911754448715" rgba="0 0 0.80000000000000004 1" mass="1"/>
          <body name="front_limb_15" pos="0 -3.2936634303524035 0">
            <joint name="front_shoulder_15" class="/" type="ball" pos="0 1.0978878101174678 0"/>
            <geom name="front_arm_15" class="/" type="box" size="0.20449955877224357 1.0978878101174678 0.20449955877224357" rgba="0 0 0.90000000000000002 1" mass="1"/>
            <body name="front_limb_16" pos="0 -1.6468317151762017 0">
              <joint name="front_shoulder_16" class="/" type="ball" pos="0 0.54894390505873392 0"/>
              <geom name="front_arm_16" class="/" type="box" size="0.10224977938612179 0.54894390505873392 0.10224977938612179" rgba="0 0 1 1" mass="1"/>
            </body>
          </body>
        </body>
      </body>
      <body name="left_limb_17" pos="-5.1620429045771639 0 0">
        <joint name="left_shoulder_17" class="/" type="ball" pos="3.9044861695420816 0 0"/>
        <geom name="left_arm_17" class="/" type="box" size="3.9044861695420816 0.53442687530776056 0.53442687530776056" rgba="0 0 1 1" mass="1"/>
      </body>
      <body name="back_limb_18" pos="0 5.1140485359909782 0">
        <joint name="back_shoulder_18" class="/" type="ball" pos="0 -3.1646919834677636 0"/>
        <geom name="back_arm_18" class="/" type="box" size="0.20000000000000001 3.1646919834677636 0.20000000000000001" rgba="0 0 1 1" mass="1"/>
      </body>
    </body>
  </worldbody>
  <actuator>
    <position name="frontxy_3" class="/" group="0" gear="0 0 1" joint="front_shoulder_13" kp="5"/>
    <position name="frontxz_3" class="/" group="0" gear="0 1 0" joint="front_shoulder_13" kp="5"/>
    <position name="frontyz_3" class="/" group="0" gear="1 0 0" joint="front_shoulder_13" kp="5"/>
    <position name="frontxy_2" class="/" group="0" gear="0 0 1" joint="front_shoulder_14" kp="5"/>
    <position name="frontxz_2" class="/" group="0" gear="0 1 0" joint="front_shoulder_14" kp="5"/>
    <position name="frontyz_2" class="/" group="0" gear="1 0 0" joint="front_shoulder_14" kp="5"/>
    <position name="frontxy_1" class="/" group="0" gear="0 0 1" joint="front_shoulder_15" kp="5"/>
    <position name="frontxz_1" class="/" group="0" gear="0 1 0" joint="front_shoulder_15" kp="5"/>
    <position name="frontyz_1" class="/" group="0" gear="1 0 0" joint="front_shoulder_15" kp="5"/>
    <position name="frontxy_0" class="/" group="0" gear="0 0 1" joint="front_shoulder_16" kp="5"/>
    <position name="frontxz_0" class="/" group="0" gear="0 1 0" joint="front_shoulder_16" kp="5"/>
    <position name="frontyz_0" class="/" group="0" gear="1 0 0" joint="front_shoulder_16" kp="5"/>
    <position name="leftxy_0" class="/" group="3" gear="0 0 1" joint="left_shoulder_17" kp="5"/>
    <position name="leftxz_0" class="/" group="3" gear="0 1 0" joint="left_shoulder_17" kp="5"/>
    <position name="leftyz_0" class="/" group="3" gear="1 0 0" joint="left_shoulder_17" kp="5"/>
    <position name="backxy_0" class="/" group="2" gear="0 0 1" joint="back_shoulder_18" kp="5"/>
    <position name="backxz_0" class="/" group="2" gear="0 1 0" joint="back_shoulder_18" kp="5"/>
    <position name="backyz_0" class="/" group="2" gear="1 0 0" joint="back_shoulder_18" kp="5"/>
  </actuator>
</mujoco>
