<mujoco model="unnamed_model">
  <default>
    <default class="/"/>
  </default>
  <worldbody>
    <light name="world_light" class="/" pos="0 0 10" dir="0 0 -1" diffuse="0.5 0.5 0.5"/>
    <geom name="ground_plane" class="/" type="plane" size="0 0 1" rgba="0.5 0 0.5 1"/>
    <body name="core_body" pos="0 0 2.5">
      <geom name="core_geom" class="/" type="box" size="0.5 0.5 2.5" rgba="0 0.90000000000000002 0 1"/>
      <joint name="first" class="/" type="free"/>
      <body name="limb1" pos="2.5 0 0">
        <joint name="shoulder1" class="/" type="ball" pos="0.5 0 0"/>
        <geom name="arm1" class="/" type="box" size="2 0.20000000000000001 0.20000000000000001"/>
      </body>
    </body>
  </worldbody>
</mujoco>
