<mujoco model="unnamed_model">
  <option timestep="0.01" integrator="RK4">
    <flag energy="enable" sensornoise="enable"/>
  </option>
  <default>
    <default class="/"/>
  </default>
  <worldbody>
    <light name="world_light" class="/" pos="0 0 10" dir="0 0 -1" diffuse="0.5 0.5 0.5"/>
    <geom name="ground_plane" class="/" type="plane" size="0 0 1" rgba="0.5 0 0.5 1"/>
    <body name="core_body" pos="0 0 2.8428504504822163">
      <geom name="core_geom" class="/" type="box" size="0.25829909574436705 1.4896065863561607 2.8428504504822163" rgba="0 0.90000000000000002 0 1"/>
      <joint name="first" class="/" type="free"/>
      <body name="front_limb_1" pos="0 -2.3244574636884394 0">
        <joint name="front_shoulder_1" class="/" type="ball" pos="0 0.8348508773322787 0"/>
        <geom name="front_arm_1" class="/" type="box" size="0.38530354521524279 0.8348508773322787 0.38530354521524279" rgba="0 0 0.80000000000000004 1" mass="1"/>
        <body name="front_limb_2" pos="0 -1.252276315998418 0">
          <joint name="front_shoulder_2" class="/" type="ball" pos="0 0.41742543866613935 0"/>
          <geom name="front_arm_2" class="/" type="box" size="0.1926517726076214 0.41742543866613935 0.1926517726076214" rgba="0 0 0.90000000000000002 1" mass="1"/>
          <body name="front_limb_3" pos="0 -0.62613815799920902 0">
            <joint name="front_shoulder_3" class="/" type="ball" pos="0 0.20871271933306967 0"/>
            <geom name="front_arm_3" class="/" type="box" size="0.096325886303810698 0.20871271933306967 0.096325886303810698" rgba="0 0 1 1" mass="1"/>
          </body>
        </body>
      </body>
      <body name="right_limb_4" pos="1.0966559147398907 0 0">
        <joint name="right_shoulder_4" class="/" type="ball" pos="-0.8383568189955235 0 0"/>
        <geom name="right_arm_4" class="/" type="box" size="0.8383568189955235 0.62551083531087848 0.62551083531087848" rgba="0 0 1 1" mass="1"/>
      </body>
      <body name="left_limb_5" pos="-3.7139440937356971 0 0">
        <joint name="left_shoulder_5" class="/" type="ball" pos="3.45564499799133 0 0"/>
        <geom name="left_arm_5" class="/" type="box" size="3.45564499799133 0.33674381982028678 0.33674381982028678" rgba="0 0 0.90000000000000002 1" mass="1"/>
        <body name="left_limb_6" pos="-5.1834674969869949 0 0">
          <joint name="left_shoulder_6" class="/" type="ball" pos="1.727822498995665 0 0"/>
          <geom name="left_arm_6" class="/" type="box" size="1.727822498995665 0.16837190991014339 0.16837190991014339" rgba="0 0 1 1" mass="1"/>
        </body>
      </body>
      <body name="back_limb_7" pos="0 3.6783064467648949 0">
        <joint name="back_shoulder_7" class="/" type="ball" pos="0 -2.1886998604087342 0"/>
        <geom name="back_arm_7" class="/" type="box" size="0.5148626766369333 2.1886998604087342 0.5148626766369333" rgba="0 0 1 1" mass="1"/>
      </body>
    </body>
  </worldbody>
  <actuator>
    <position name="frontxy_2" class="/" group="0" gear="0 0 1" joint="front_shoulder_1" kp="5"/>
    <position name="frontxz_2" class="/" group="0" gear="0 1 0" joint="front_shoulder_1" kp="5"/>
    <position name="frontyz_2" class="/" group="0" gear="1 0 0" joint="front_shoulder_1" kp="5"/>
    <position name="frontxy_1" class="/" group="0" gear="0 0 1" joint="front_shoulder_2" kp="5"/>
    <position name="frontxz_1" class="/" group="0" gear="0 1 0" joint="front_shoulder_2" kp="5"/>
    <position name="frontyz_1" class="/" group="0" gear="1 0 0" joint="front_shoulder_2" kp="5"/>
    <position name="frontxy_0" class="/" group="0" gear="0 0 1" joint="front_shoulder_3" kp="5"/>
    <position name="frontxz_0" class="/" group="0" gear="0 1 0" joint="front_shoulder_3" kp="5"/>
    <position name="frontyz_0" class="/" group="0" gear="1 0 0" joint="front_shoulder_3" kp="5"/>
    <position name="rightxy_0" class="/" group="1" gear="0 0 1" joint="right_shoulder_4" kp="5"/>
    <position name="rightxz_0" class="/" group="1" gear="0 1 0" joint="right_shoulder_4" kp="5"/>
    <position name="rightyz_0" class="/" group="1" gear="1 0 0" joint="right_shoulder_4" kp="5"/>
    <position name="leftxy_1" class="/" group="3" gear="0 0 1" joint="left_shoulder_5" kp="5"/>
    <position name="leftxz_1" class="/" group="3" gear="0 1 0" joint="left_shoulder_5" kp="5"/>
    <position name="leftyz_1" class="/" group="3" gear="1 0 0" joint="left_shoulder_5" kp="5"/>
    <position name="leftxy_0" class="/" group="3" gear="0 0 1" joint="left_shoulder_6" kp="5"/>
    <position name="leftxz_0" class="/" group="3" gear="0 1 0" joint="left_shoulder_6" kp="5"/>
    <position name="leftyz_0" class="/" group="3" gear="1 0 0" joint="left_shoulder_6" kp="5"/>
    <position name="backxy_0" class="/" group="2" gear="0 0 1" joint="back_shoulder_7" kp="5"/>
    <position name="backxz_0" class="/" group="2" gear="0 1 0" joint="back_shoulder_7" kp="5"/>
    <position name="backyz_0" class="/" group="2" gear="1 0 0" joint="back_shoulder_7" kp="5"/>
  </actuator>
</mujoco>
